[21/04/2018 17:03] ERROR red load_cogs 573: ffmpeg isn't installed.
Consult the guide for your operating system and do ALL the steps in order.
https://twentysix26.github.io/Red-Docs/
Traceback (most recent call last):
  File "red.py", line 570, in load_cogs
    owner_cog._load_cog(extension)
  File "C:\Users\Danny\Desktop\RedBot\Red-DiscordBot\cogs\owner.py", line 948, in _load_cog
    self.bot.load_extension(mod_obj.__name__)
  File "lib\discord\ext\commands\bot.py", line 738, in load_extension
    lib.setup(self)
  File "C:\Users\Danny\Desktop\RedBot\Red-DiscordBot\cogs\audio.py", line 2549, in setup
    "".format(msg))
RuntimeError: ffmpeg isn't installed.
Consult the guide for your operating system and do ALL the steps in order.
https://twentysix26.github.io/Red-Docs/

[21/04/2018 17:03] ERROR red <module> 616: Traceback (most recent call last):
  File "lib\discord\http.py", line 258, in static_login
    data = yield from self.request(Route('GET', '/users/@me'))
  File "lib\discord\http.py", line 200, in request
    raise HTTPException(r, data)
discord.errors.HTTPException: UNAUTHORIZED (status code: 401): 401: Unauthorized

The above exception was the direct cause of the following exception:

Traceback (most recent call last):
  File "red.py", line 614, in <module>
    loop.run_until_complete(main(bot))
  File "C:\Users\Danny\AppData\Local\Programs\Python\Python35\lib\asyncio\base_events.py", line 387, in run_until_complete
    return future.result()
  File "C:\Users\Danny\AppData\Local\Programs\Python\Python35\lib\asyncio\futures.py", line 274, in result
    raise self._exception
  File "C:\Users\Danny\AppData\Local\Programs\Python\Python35\lib\asyncio\tasks.py", line 239, in _step
    result = coro.send(None)
  File "red.py", line 599, in main
    bot=not bot.settings.self_bot)
  File "lib\discord\client.py", line 416, in login
    yield from getattr(self, '_login_' + str(n))(*args, **kwargs)
  File "lib\discord\client.py", line 346, in _login_1
    data = yield from self.http.static_login(token, bot=is_bot)
  File "lib\discord\http.py", line 262, in static_login
    raise LoginFailure('Improper token has been passed.') from e
discord.errors.LoginFailure: Improper token has been passed.

[21/04/2018 17:04] ERROR red <module> 616: Traceback (most recent call last):
  File "lib\discord\http.py", line 258, in static_login
    data = yield from self.request(Route('GET', '/users/@me'))
  File "lib\discord\http.py", line 200, in request
    raise HTTPException(r, data)
discord.errors.HTTPException: UNAUTHORIZED (status code: 401): 401: Unauthorized

The above exception was the direct cause of the following exception:

Traceback (most recent call last):
  File "red.py", line 614, in <module>
    loop.run_until_complete(main(bot))
  File "C:\Users\Danny\AppData\Local\Programs\Python\Python35\lib\asyncio\base_events.py", line 387, in run_until_complete
    return future.result()
  File "C:\Users\Danny\AppData\Local\Programs\Python\Python35\lib\asyncio\futures.py", line 274, in result
    raise self._exception
  File "C:\Users\Danny\AppData\Local\Programs\Python\Python35\lib\asyncio\tasks.py", line 239, in _step
    result = coro.send(None)
  File "red.py", line 599, in main
    bot=not bot.settings.self_bot)
  File "lib\discord\client.py", line 416, in login
    yield from getattr(self, '_login_' + str(n))(*args, **kwargs)
  File "lib\discord\client.py", line 346, in _login_1
    data = yield from self.http.static_login(token, bot=is_bot)
  File "lib\discord\http.py", line 262, in static_login
    raise LoginFailure('Improper token has been passed.') from e
discord.errors.LoginFailure: Improper token has been passed.

[21/04/2018 18:43] INFO economy _set 380: Zykrah(221241527240884224) added 1000 credits to Zykrah (221241527240884224)
[21/04/2018 18:43] INFO economy _set 380: Zykrah(221241527240884224) added 100 credits to Annoyance.says (371977548432801793)
